<?xml version="1.0" ?>
<robot name="atl_viz" xmlns:xacro="http://ros.org/wiki/xacro">

  <!-- ****************** ROBOT CONSTANTS *******************************  -->
  <!-- Define the size of the robot's main chassis in meters -->
  <!-- <xacro:property name="base_width" value="0.39"/>
  <xacro:property name="base_length" value="0.70"/>
  <xacro:property name="base_height" value="0.20"/> -->


  <!-- ********************** BOAT ******************************  -->
  <link name="boat">
    <visual>
      <origin xyz="0 0 0" rpy="0 0 0"/>
      <geometry>
        <mesh filename="package://atl_viz/meshes/heron_base.stl" scale="1 1 1" />
      </geometry>
      <material name="dark_gray">
        <color rgba="${220/255} ${220/255} ${220/255} 1.0"/>
      </material>
    </visual>
    <inertial>
      <mass value="1"/>
      <inertia ixx="1" ixy="0" ixz="0" iyy="1" iyz="0" izz="1"/>
    </inertial>
  </link>


<!-- BODY  -->
  <link name="paravane">
    <visual>
      <origin xyz="-5 0 0" rpy="0 0 0"/>
      <geometry>
        <mesh filename="package://atl_viz/meshes/fuselage_axis.stl" scale="0.001 0.001 0.001" />
      </geometry>
      <material name="Red">
        <color rgba="${173/255} ${178/255} ${189/255} 1.0"/>
      </material>
    </visual>
    <inertial>
      <mass value="1"/>
      <inertia ixx="1" ixy="0" ixz="0" iyy="1" iyz="0" izz="1"/>
    </inertial>
  </link>

  <joint name="joint0" type="floating">
    <parent link="boat"/>
    <child link="paravane"/>
    <origin xyz="-5 0 0" rpy="0 0 0"/>
    <limit upper="3.1415" lower="-3.1415" effort="30" velocity="5.0"/>
    <!-- <axis xyz="0 1 0"/> -->
  </joint>

  <!-- ******************* MAIN WING ***************************  -->
    <link name="main_wing">
      <visual>
        <origin xyz="0 0 0" rpy="0 0 0"/>
        <geometry>
            <mesh filename="package://atl_viz/meshes/main_wing_axis.stl" scale="0.001 0.001 0.001"/>
        </geometry>
        <material name="White">
          <color rgba="${216/255} ${214/255} ${200/255} 1.0"/>
        </material>
      </visual>
      <inertial>
        <mass value="1"/>
        <inertia ixx="1" ixy="0" ixz="0" iyy="1" iyz="0" izz="1"/>
      </inertial>
    </link>

    <joint name="main_wing" type="revolute">
      <parent link="paravane"/>
      <child link="main_wing"/>
      <origin xyz="0 0 0" rpy="0 0 0"/>
      <limit upper="3.1415" lower="-3.1415" effort="30" velocity="5.0"/>
      <axis xyz="0 1 0"/>
    </joint>


  <!-- FINS -->
  <xacro:macro name="actuator" params="postfix x_reflect y_reflect z_reflect r_rot_reflect p_rot_reflect y_rot_reflect">
    <link name="actuator${postfix}">
      <visual>
        <origin xyz="${x_reflect} ${y_reflect} ${z_reflect}" rpy="0 0 0"/>
        <geometry>
            <mesh filename="package://atl_viz/meshes/tail_fin_axis.stl" scale="0.001 0.001 0.001"/>
        </geometry>
        <material name="White">
          <color rgba="${0/255} ${0/255} ${0/255} 1.0"/>
        </material>
      </visual>
      <inertial>
        <mass value="1"/>
        <inertia ixx="1" ixy="0" ixz="0" iyy="1" iyz="0" izz="1"/>
      </inertial>
    </link>

    <joint name="joint${postfix}" type="revolute">
      <parent link="paravane"/>
      <child link="actuator${postfix}"/>
      <origin xyz="${x_reflect} ${y_reflect} ${z_reflect}" rpy="${r_rot_reflect} ${p_rot_reflect} ${y_rot_reflect}"/>
      <limit upper="3.1415" lower="-3.1415" effort="30" velocity="5.0"/>
      <axis xyz="0 0 1"/>
    </joint>
  </xacro:macro>

<xacro:actuator postfix="1" x_reflect="-0.1" y_reflect="0" z_reflect="-0.1" r_rot_reflect="0" p_rot_reflect="0.0" y_rot_reflect="0.0"/>
<xacro:actuator postfix="2" x_reflect="-0.15" y_reflect="0.02" z_reflect="0.075" r_rot_reflect="0" p_rot_reflect="0.0" y_rot_reflect="0.0"/>
<xacro:actuator postfix="3" x_reflect="-0.15" y_reflect="-0.02" z_reflect="0.075" r_rot_reflect="0" p_rot_reflect="0" y_rot_reflect="0.0"/>

</robot>